<?xml version="1.0" ?>
<!-- =================================================================================== -->
<!-- |    This document was autogenerated by xacro from /home/catkin_ws/src/nist_description/boards/routing.xacro | -->
<!-- |    EDITING THIS FILE BY HAND IS NOT RECOMMENDED                                 | -->
<!-- =================================================================================== -->
<robot name="test">
  <!-- Define the hand_tcp frame -->
  <link name="clip_complex_base_0">
    <visual>
      <geometry>
        <mesh filename="package://nist_description/models/clip_ethernet_orizzontale_base_scaled.stl"/>
      </geometry>
    </visual>
    <!-- <collision>
        <origin xyz="0 0 -5.5e-3" rpy="0 0 0" />
        <geometry>
            <cylinder length="11e-3" radius="40e-3"/>
        </geometry>
      </collision> -->
  </link>
  <link name="clip_complex_0">
    <visual>
      <geometry>
        <mesh filename="package://nist_description/models/clip_ethernet_orizzontale_top_scaled.stl"/>
      </geometry>
    </visual>
    <!-- <collision>
        <origin xyz="0 0 -5.5e-3" rpy="0 0 0" />
        <geometry>
            <cylinder length="11e-3" radius="40e-3"/>
        </geometry>
      </collision> -->
  </link>
  <joint name="BTT_clip_complex_base_0" type="revolute">
    <parent link="clip_complex_base_0"/>
    <child link="clip_complex_0"/>
    <origin rpy="0 0 0" xyz="-0.0117 0 0.015"/>
    <limit effort="1000" lower="0" upper="-3.141592653589793" velocity="6.28"/>
  </joint>
</robot>

